Workbook

Sheet Overview
B2: Student Academic Performance Analytics
B3: Excel-Based Business Analytics Project
B4: Self project by Shristi Sharma
B6: Project Objective
B7: Analyze student academic performance, attendance, study habits, motivation, and related factors to identify patterns and generate actionable insights using Excel-based Business Analytics.
B9: Project Workflow
B10: Data Collection | J10: → | L10: Data Cleaning | T10: → | V10: Exploratory Analysis | AD10: → | AF10: Visualization | AN10: → | AP10: Insights | AX10: → | AZ10: Recommendations
B12: Tools Used
B13: Tool | V13: Purpose
B14: Microsoft Excel | V14: Data cleaning, analysis & visualization
B15: Pivot Tables | V15: Group-wise analysis
B16: Charts & Dashboard | V16: Visual storytelling
B17: Statistical Analysis | V17: Performance & relationship analysis
B19: Key Areas Analyzed
B20: 📊 Academic Performance | N20: 📅 Attendance | Z20: 📚 Study Habits | AL20: 🎯 Student Motivation | AX20: 🏫 Institution & Field
B22: Dataset Overview
B23: The dataset contains student-level academic and behavioral information, including examination performance, attendance, study habits, motivation, academic confidence, field of study, year of study, and institution.
B24: Collected through a short Google Form: 65 responses, 8 self-rating questions on a 1-6 scale. Small sample, reached directly and self-reported, so findings describe this group only.
B26: Sheets in this Workbook
B27: 2. Raw Data | N27: Original survey export, untouched.
B28: 3. Cleaning Log | N28: Every fix made and how many rows it touched.
B29: 4. Cleaned Data | N29: Survey data after cleaning, with calculated columns and a cleaning note per row.
B30: 5. Analysis | N30: All tables, statistics, key questions and recommendations, built with formulas.
B31: 6. Dashboard | N31: One-page summary: KPIs, five charts and three insight cards.
B32: 7. Assumptions | N32: Conversion rules and cut-offs. Change a blue cell and everything updates.
B34: Flow: Raw Data → Cleaned Data → Analysis → Dashboard

Sheet Raw Data
A1: Timestamp | B1: 1. What type of institution do you study in? | C1: 2. What is your field of study? | D1: 3. What year of study are you currently in? | E1: 4. Which city do you currently study in? | F1: 5. What was your percentage in your most recent semester/examination? | G1: Approximately what is your average class attendance? | H1: 1. How satisfied are you with your overall academic performance? | I1: 2. How confident are you in your ability to perform well academically? | J1: 3. How consistent are you with your study routine? | K1: 4. How well do you understand the subjects you are currently studying? | L1: 5. How motivated are you to study regularly? | M1: 6. How effectively do you manage your study time? | N1: 7. How focused are you while studying? | O1: 8. How much do you feel your attendance contributes to your academic performance?
A2: 46293.624 | B2: Private | C2: Business/Management | D2: 2nd year | E2: Mehsana | F2: 8.96 cgpa | G2: 51-60% | H2: 2 | I2: 5 | J2: 3 | K2: 3 | L2: 3 | M2: 3 | N2: 5 | O2: 2
A3: 46293.624 | B3: Private | C3: Computer Science/IT | D3: 2nd year | E3: Greater Noida | F3: 0.78 | G3: below 50% | H3: 4 | I3: 6 | J3: 2 | K3: 5 | L3: 1 | M3: 2 | N3: 4 | O3: 1
A4: 46293.627 | B4: Private | C4: Commerce | D4: 2nd year | E4: Mehsana | F4: 0.7 | G4: 61-70% | H4: 1 | I4: 2 | J4: 1 | K4: 3 | L4: 1 | M4: 2 | N4: 3 | O4: 2
A5: 46293.627 | B5: Private | C5: Engineering | D5: 2nd year | E5: Mehsana | F5: 0.87 | G5: 71-80% | H5: 5 | I5: 6 | J5: 6 | K5: 6 | L5: 5 | M5: 4 | N5: 6 | O5: 4
A6: 46293.632 | B6: Private | C6: Physical education | D6: 1st year | E6: Punjab | F6: Nil | G6: 91-100% | H6: 5 | I6: 4 | J6: 3 | K6: 5 | L6: 5 | M6: 4 | N6: 4 | O6: 6
A7: 46293.633 | B7: Government | C7: Commerce | D7: 1st year | E7: Kolkata | F7: No examination yet | G7: 71-80% | H7: 4 | I7: 4 | J7: 2 | K7: 4 | L7: 3 | M7: 3 | N7: 2 | O7: 4
A8: 46293.634 | B8: Private | C8: Biotechnology | D8: 1st year | E8: Kolkata | F8: 0.43 | G8: 81-90% | H8: 4 | I8: 4 | J8: 3 | K8: 4 | L8: 5 | M8: 3 | N8: 3 | O8: 5
A9: 46293.634 | B9: Private | C9: Computer Science/IT | D9: 2nd year | E9: Durgapur | F9: 6.5 cgpa | G9: below 50% | H9: 3 | I9: 4 | J9: 2 | K9: 4 | L9: 3 | M9: 2 | N9: 5 | O9: 4
A10: 46293.635 | B10: Private | C10: Arts/Humanities | D10: 1st year | E10: Kolkata | F10: 0.6 | G10: 61-70% | H10: 3 | I10: 3 | J10: 2 | K10: 4 | L10: 4 | M10: 3 | N10: 5 | O10: 4
A11: 46293.636 | B11: Private | C11: Business/Management | D11: 2nd year | E11: Durgapur | F11: 0.64 | G11: 61-70% | H11: 5 | I11: 6 | J11: 5 | K11: 6 | L11: 2 | M11: 5 | N11: 6 | O11: 6
A12: 46293.637 | B12: Government | C12: Commerce | D12: 2nd year | E12: Durgapur | F12: 6.80 sgpa | G12: 51-60% | H12: 2 | I12: 5 | J12: 5 | K12: 5 | L12: 5 | M12: 5 | N12: 5 | O12: 5
A13: 46293.638 | B13: Private | C13: Arts/Humanities | D13: 1st | E13: Murshidabad | F13: 0.68 | G13: 51-60% | H13: 3 | I13: 4 | J13: 3 | K13: 5 | L13: 4 | M13: 3 | N13: 3 | O13: 4
A14: 46293.641 | B14: Private | C14: Business/Management | D14: 2nd year | E14: Mehsana (Gujarat) | F14: 0.5 | G14: 51-60% | H14: 6 | I14: 4 | J14: 6 | K14: 6 | L14: 6 | M14: 6 | N14: 6 | O14: 1
A15: 46293.642 | B15: Private | C15: Business/Management | D15: 3rd year | E15: Ghaziabad | F15: 0.7 | G15: 71-80% | H15: 5 | I15: 6 | J15: 6 | K15: 6 | L15: 6 | M15: 6 | N15: 6 | O15: 1
A16: 46293.646 | B16: Private | C16: Business/Management | D16: 1st year | E16: Mohali | F16: 0.67 | G16: 91-100% | H16: 4 | I16: 5 | J16: 3 | K16: 6 | L16: 4 | M16: 5 | N16: 5 | O16: 5
A17: 46293.646 | B17: Government-aided | C17: Medicine/Healthcare | D17: 4th year | E17: Delhi | F17: 9.7 cgpa | G17: 71-80% | H17: 3 | I17: 4 | J17: 5 | K17: 6 | L17: 2 | M17: 4 | N17: 5 | O17: 6
A18: 46293.649 | B18: Private | C18: Commerce | D18: 1st year | E18: Prayagraj | F18: 8.01 cgpa | G18: 71-80% | H18: 6 | I18: 6 | J18: 5 | K18: 4 | L18: 5 | M18: 5 | N18: 5 | O18: 4
A19: 46293.649 | B19: Government | C19: Engineering | D19: 1st year | E19: Burdwan | F19: 2 cgpa | G19: 51-60% | H19: 3 | I19: 2 | J19: 3 | K19: 4 | L19: 3 | M19: 4 | N19: 2 | O19: 1
A20: 46293.651 | B20: Private | C20: Commerce | D20: 2nd year | E20: Delhi | F20: 0.64 | G20: 61-70% | H20: 4 | I20: 5 | J20: 4 | K20: 4 | L20: 3 | M20: 5 | N20: 5 | O20: 2
A21: 46293.651 | B21: Government-aided | C21: Arts/Humanities | D21: 3rd year | E21: Hyderabad | F21: 6.7 cgpa | G21: 71-80% | H21: 6 | I21: 4 | J21: 2 | K21: 1 | L21: 3 | M21: 1 | N21: 6 | O21: 5
A22: 46293.655 | B22: Government | C22: Medicine/Healthcare | D22: 3rd year | E22: Kolkata | F22: 0.8 | G22: 91-100% | H22: 4 | I22: 3 | J22: 2 | K22: 4 | L22: 5 | M22: 3 | N22: 2 | O22: 1
A23: 46293.66 | B23: Government | C23: Arts/Humanities | D23: 2nd year | E23: Durgapur | F23: 0.67 | G23: 61-70% | H23: 4 | I23: 2 | J23: 3 | K23: 4 | L23: 3 | M23: 3 | N23: 2 | O23: 4
A24: 46293.66 | B24: Private | C24: Engineering | D24: 4th year | E24: Mehsana | F24: 6.3 cgpa | G24: 51-60% | H24: 3 | I24: 2 | J24: 2 | K24: 3 | L24: 1 | M24: 1 | N24: 2 | O24: 2
A25: 46293.664 | B25: Private | C25: Computer Science/IT | D25: 2nd year | E25: Chattisgarh | F25: 0.65 | G25: below 50% | H25: 4 | I25: 2 | J25: 2 | K25: 2 | L25: 1 | M25: 3 | N25: 2 | O25: 1
A26: 46293.668 | B26: Government | C26: Arts/Humanities | D26: 4th year | E26: Durgapur | F26: 0.7 | G26: 91-100% | H26: 4 | I26: 4 | J26: 5 | K26: 5 | L26: 3 | M26: 4 | N26: 4 | O26: 4
A27: 46293.668 | B27: Government | C27: Arts/Humanities | D27: 4th year | E27: West Bengal | F27: 0.63 | G27: 61-70% | H27: 1 | I27: 4 | J27: 3 | K27: 4 | L27: 5 | M27: 6 | N27: 3 | O27: 3
A28: 46293.672 | B28: Government | C28: Business/Management | D28: 4th year | E28: Durgapur | F28: 0.7 | G28: 71-80% | H28: 6 | I28: 6 | J28: 6 | K28: 5 | L28: 6 | M28: 6 | N28: 6 | O28: 6
A29: 46293.672 | B29: Private | C29: Business/Management | D29: 2nd year | E29: Mehsana | F29: 0.7 | G29: 71-80% | H29: 4 | I29: 6 | J29: 5 | K29: 6 | L29: 5 | M29: 6 | N29: 6 | O29: 6
A30: 46293.686 | B30: Government-aided | C30: BA LLB | D30: 2nd year | E30: ahmedabad | F30: 8.09 cgpa | G30: 71-80% | H30: 3 | I30: 4 | J30: 3 | K30: 4 | L30: 3 | M30: 4 | N30: 3 | O30: 4
A31: 46293.701 | B31: Government-aided | C31: Medicine/Healthcare | D31: 1st year | E31: Kolkata | F31: 0.8 | G31: 61-70% | H31: 4 | I31: 4 | J31: 1 | K31: 4 | L31: 2 | M31: 2 | N31: 2 | O31: 2
A32: 46293.72 | B32: Government | C32: Business/Management | D32: 2nd year | E32: Kolkata | F32: 7.8 cgpa | G32: 61-70% | H32: 3 | I32: 5 | J32: 6 | K32: 5 | L32: 6 | M32: 5 | N32: 6 | O32: 6
A33: 46293.721 | B33: Private | C33: Business/Management | D33: 2nd year | E33: Greater Noida | F33: 0.78 | G33: 71-80% | H33: 3 | I33: 5 | J33: 4 | K33: 3 | L33: 5 | M33: 4 | N33: 5 | O33: 2
A34: 46293.722 | B34: Non Profit organizations | C34: Computer Science/IT | D34: 3rd year | E34: Asansol | F34: 0.9 | G34: 81-90% | H34: 5 | I34: 5 | J34: 4 | K34: 6 | L34: 5 | M34: 5 | N34: 3 | O34: 3
A35: 46293.723 | B35: Private | C35: Computer Science/IT | D35: 3rd year | E35: Mehsana | F35: 0.78 | G35: 81-90% | H35: 5 | I35: 5 | J35: 5 | K35: 5 | L35: 5 | M35: 5 | N35: 5 | O35: 4
A36: 46293.723 | B36: Government-aided | C36: BBA LLB | D36: 4th year | E36: Chandigarh | F36: 9.3 sgpa | G36: 61-70% | H36: 5 | I36: 3 | J36: 3 | K36: 4 | L36: 3 | M36: 4 | N36: 4 | O36: 5
A37: 46293.725 | B37: Private | C37: Engineering | D37: 2nd year | E37: Amritsar | F37: 0.67 | G37: 61-70% | H37: 4 | J37: 3 | K37: 4 | L37: 5 | M37: 6 | N37: 4 | O37: 6
A38: 46293.726 | B38: Government | C38: Arts/Humanities | D38: 3rd year | E38: Delhi | F38: 7.8cgpa | G38: 71-80% | H38: 3 | I38: 4 | J38: 3 | K38: 3 | L38: 4 | M38: 2 | N38: 4 | O38: 5
A39: 46293.726 | B39: Private | C39: Engineering | D39: 3rd year | E39: Durgapur | F39: 0.73 | G39: 81-90% | H39: 4 | I39: 3 | J39: 2 | K39: 5 | L39: 4 | M39: 3 | N39: 4 | O39: 5
A40: 46293.727 | B40: Government-aided | C40: BA psychology | D40: 3rd year | E40: Kolkata | F40: 9.5cgpa | G40: 71-80% | H40: 3 | I40: 4 | J40: 5 | K40: 6 | L40: 3 | M40: 4 | N40: 5 | O40: 6
...

Sheet Cleaning Log
A1: What I changed in the raw data, and why
A3: # | B3: What was wrong | C3: What I did | D3: Rows affected
A4: 1 | B4: Marks typed as CGPA / SGPA text (e.g. "8.96 cgpa") | C4: Pulled out the number and converted to a percentage using the multiplier in Assumptions. | D4: =COUNTIF('Cleaned Data'!$W$2:$W$66,"*GPA to %*") -> 22
A5: 2 | B5: Marks entered as a decimal (0.78 instead of 78%) | C5: Multiplied by 100 so it reads as a percentage. | D5: =COUNTIF('Cleaned Data'!$W$2:$W$66,"*decimal to %*") -> 40
A6: 3 | B6: No marks given ("Nil", "No examination yet") | C6: Kept the student in the survey but left them out of score calculations. | D6: =COUNTIF('Cleaned Data'!$W$2:$W$66,"*no score*") -> 2
A7: 4 | B7: One score looked like a typing mistake (2 CGPA, about 19%) | C7: Flagged it and left it out of score analysis. Their other answers still count. | D7: =COUNTIF('Cleaned Data'!$W$2:$W$66,"*implausible score*") -> 1
A8: 5 | B8: Year typed as "1st" instead of "1st year" | C8: Made it match the other labels. | D8: =COUNTIF('Cleaned Data'!$W$2:$W$66,"*year label fixed*") -> 1
A9: 6 | B9: City names with extra spaces, small letters or spelling slips (e.g. ahmedabad, Mehsana (Gujarat), Telegana) | C9: Trimmed spaces and corrected spelling so the same city is not counted twice. | D9: =COUNTIF('Cleaned Data'!$W$2:$W$66,"*city fixed*") -> 29
A10: 7 | B10: Fields of study typed freely (BA LLB, Bsc chemistry, BA ECONOMICS...) | C10: Grouped into broader fields. Very small ones share a "Law/Science/Other" group. | D10: =COUNTIF('Cleaned Data'!$W$2:$W$66,"*field regrouped*") -> 8
A11: 8 | B11: One response from a non-profit institution | C11: Labelled "Other (Non-profit)". Only 1 student, so I do not compare it with the others. | D11: =COUNTIF('Cleaned Data'!$W$2:$W$66,"*institution regrouped*") -> 1
A12: 9 | B12: One student skipped the Confidence question | C12: Left blank. Averages ignore blanks. | D12: =COUNTIF('Cleaned Data'!$W$2:$W$66,"*confidence blank*") -> 1
A13: 10 | B13: Duplicate responses | C13: Checked every column (except timestamp). None found, so no rows were removed. | D13: 0
A15: Duplicates count was checked in Python when I built the file; all other counts above are live formulas on the Cleaned Data sheet.
A16: The Raw Data sheet is untouched. Only header styling was added so it is readable.

Sheet Cleaned Data
A1: ID | B1: Institution Type | C1: Field Group | D1: Study Year | E1: City | F1: Score Type | G1: Score Reported | H1: Score (%) | I1: Valid Score? | J1: Score Used (%) | K1: Attendance Band | L1: Attendance Midpoint (%) | M1: Satisfaction | N1: Confidence | O1: Consistency | P1: Understanding | Q1: Motivation | R1: Time Management | S1: Focus | T1: Attendance Impact (perceived) | U1: Study Habit Index (1-6) | V1: Habit Group | W1: Cleaning Note
A2: 1 | B2: Private | C2: Business/Management | D2: 2nd year | E2: Mehsana | F2: CGPA | G2: 8.96 | H2: =IF(F2="Percentage",G2,IF(OR(F2="CGPA",F2="SGPA"),G2*Assumptions!$B$3,"")) -> 85.12 | I2: =IF(AND(ISNUMBER(H2),H2>=Assumptions!$B$4),"Yes","No") -> Yes | J2: =IF(I2="Yes",H2,"") -> 85.12 | K2: 51-60% | L2: =INDEX(Assumptions!$B$10:$B$15,MATCH(K2,Assumptions!$A$10:$A$15,0)) -> 55 | M2: 2 | N2: 5 | O2: 3 | P2: 3 | Q2: 3 | R2: 3 | S2: 5 | T2: 2 | U2: =AVERAGE(O2,Q2,R2,S2) -> 3.5 | V2: =IF(U2<Assumptions!$B$5,"Low",IF(U2>=Assumptions!$B$6,"High","Medium")) -> Medium | W2: city fixed; GPA to %
A3: 2 | B3: Private | C3: Computer Science/IT | D3: 2nd year | E3: Greater Noida | F3: Percentage | G3: 78 | H3: =IF(F3="Percentage",G3,IF(OR(F3="CGPA",F3="SGPA"),G3*Assumptions!$B$3,"")) -> 78 | I3: =IF(AND(ISNUMBER(H3),H3>=Assumptions!$B$4),"Yes","No") -> Yes | J3: =IF(I3="Yes",H3,"") -> 78 | K3: below 50% | L3: =INDEX(Assumptions!$B$10:$B$15,MATCH(K3,Assumptions!$A$10:$A$15,0)) -> 45 | M3: 4 | N3: 6 | O3: 2 | P3: 5 | Q3: 1 | R3: 2 | S3: 4 | T3: 1 | U3: =AVERAGE(O3,Q3,R3,S3) -> 2.25 | V3: =IF(U3<Assumptions!$B$5,"Low",IF(U3>=Assumptions!$B$6,"High","Medium")) -> Low | W3: city fixed; decimal to %
A4: 3 | B4: Private | C4: Commerce | D4: 2nd year | E4: Mehsana | F4: Percentage | G4: 70 | H4: =IF(F4="Percentage",G4,IF(OR(F4="CGPA",F4="SGPA"),G4*Assumptions!$B$3,"")) -> 70 | I4: =IF(AND(ISNUMBER(H4),H4>=Assumptions!$B$4),"Yes","No") -> Yes | J4: =IF(I4="Yes",H4,"") -> 70 | K4: 61-70% | L4: =INDEX(Assumptions!$B$10:$B$15,MATCH(K4,Assumptions!$A$10:$A$15,0)) -> 65 | M4: 1 | N4: 2 | O4: 1 | P4: 3 | Q4: 1 | R4: 2 | S4: 3 | T4: 2 | U4: =AVERAGE(O4,Q4,R4,S4) -> 1.75 | V4: =IF(U4<Assumptions!$B$5,"Low",IF(U4>=Assumptions!$B$6,"High","Medium")) -> Low | W4: city fixed; decimal to %
A5: 4 | B5: Private | C5: Engineering | D5: 2nd year | E5: Mehsana | F5: Percentage | G5: 87 | H5: =IF(F5="Percentage",G5,IF(OR(F5="CGPA",F5="SGPA"),G5*Assumptions!$B$3,"")) -> 87 | I5: =IF(AND(ISNUMBER(H5),H5>=Assumptions!$B$4),"Yes","No") -> Yes | J5: =IF(I5="Yes",H5,"") -> 87 | K5: 71-80% | L5: =INDEX(Assumptions!$B$10:$B$15,MATCH(K5,Assumptions!$A$10:$A$15,0)) -> 75 | M5: 5 | N5: 6 | O5: 6 | P5: 6 | Q5: 5 | R5: 4 | S5: 6 | T5: 4 | U5: =AVERAGE(O5,Q5,R5,S5) -> 5.25 | V5: =IF(U5<Assumptions!$B$5,"Low",IF(U5>=Assumptions!$B$6,"High","Medium")) -> High | W5: city fixed; decimal to %
A6: 5 | B6: Private | C6: Law/Science/Other | D6: 1st year | E6: Punjab | F6: Not available | H6: =IF(F6="Percentage",G6,IF(OR(F6="CGPA",F6="SGPA"),G6*Assumptions!$B$3,"")) | I6: =IF(AND(ISNUMBER(H6),H6>=Assumptions!$B$4),"Yes","No") -> No | J6: =IF(I6="Yes",H6,"") | K6: 91-100% | L6: =INDEX(Assumptions!$B$10:$B$15,MATCH(K6,Assumptions!$A$10:$A$15,0)) -> 95 | M6: 5 | N6: 4 | O6: 3 | P6: 5 | Q6: 5 | R6: 4 | S6: 4 | T6: 6 | U6: =AVERAGE(O6,Q6,R6,S6) -> 4 | V6: =IF(U6<Assumptions!$B$5,"Low",IF(U6>=Assumptions!$B$6,"High","Medium")) -> Medium | W6: field regrouped; no score
A7: 6 | B7: Government | C7: Commerce | D7: 1st year | E7: Kolkata | F7: Not available | H7: =IF(F7="Percentage",G7,IF(OR(F7="CGPA",F7="SGPA"),G7*Assumptions!$B$3,"")) | I7: =IF(AND(ISNUMBER(H7),H7>=Assumptions!$B$4),"Yes","No") -> No | J7: =IF(I7="Yes",H7,"") | K7: 71-80% | L7: =INDEX(Assumptions!$B$10:$B$15,MATCH(K7,Assumptions!$A$10:$A$15,0)) -> 75 | M7: 4 | N7: 4 | O7: 2 | P7: 4 | Q7: 3 | R7: 3 | S7: 2 | T7: 4 | U7: =AVERAGE(O7,Q7,R7,S7) -> 2.5 | V7: =IF(U7<Assumptions!$B$5,"Low",IF(U7>=Assumptions!$B$6,"High","Medium")) -> Low | W7: city fixed; no score
A8: 7 | B8: Private | C8: Law/Science/Other | D8: 1st year | E8: Kolkata | F8: Percentage | G8: 43 | H8: =IF(F8="Percentage",G8,IF(OR(F8="CGPA",F8="SGPA"),G8*Assumptions!$B$3,"")) -> 43 | I8: =IF(AND(ISNUMBER(H8),H8>=Assumptions!$B$4),"Yes","No") -> Yes | J8: =IF(I8="Yes",H8,"") -> 43 | K8: 81-90% | L8: =INDEX(Assumptions!$B$10:$B$15,MATCH(K8,Assumptions!$A$10:$A$15,0)) -> 85 | M8: 4 | N8: 4 | O8: 3 | P8: 4 | Q8: 5 | R8: 3 | S8: 3 | T8: 5 | U8: =AVERAGE(O8,Q8,R8,S8) -> 3.5 | V8: =IF(U8<Assumptions!$B$5,"Low",IF(U8>=Assumptions!$B$6,"High","Medium")) -> Medium | W8: field regrouped; city fixed; decimal to %
A9: 8 | B9: Private | C9: Computer Science/IT | D9: 2nd year | E9: Durgapur | F9: CGPA | G9: 6.5 | H9: =IF(F9="Percentage",G9,IF(OR(F9="CGPA",F9="SGPA"),G9*Assumptions!$B$3,"")) -> 61.75 | I9: =IF(AND(ISNUMBER(H9),H9>=Assumptions!$B$4),"Yes","No") -> Yes | J9: =IF(I9="Yes",H9,"") -> 61.75 | K9: below 50% | L9: =INDEX(Assumptions!$B$10:$B$15,MATCH(K9,Assumptions!$A$10:$A$15,0)) -> 45 | M9: 3 | N9: 4 | O9: 2 | P9: 4 | Q9: 3 | R9: 2 | S9: 5 | T9: 4 | U9: =AVERAGE(O9,Q9,R9,S9) -> 3 | V9: =IF(U9<Assumptions!$B$5,"Low",IF(U9>=Assumptions!$B$6,"High","Medium")) -> Low | W9: city fixed; GPA to %
A10: 9 | B10: Private | C10: Arts/Humanities | D10: 1st year | E10: Kolkata | F10: Percentage | G10: 60 | H10: =IF(F10="Percentage",G10,IF(OR(F10="CGPA",F10="SGPA"),G10*Assumptions!$B$3,"")) -> 60 | I10: =IF(AND(ISNUMBER(H10),H10>=Assumptions!$B$4),"Yes","No") -> Yes | J10: =IF(I10="Yes",H10,"") -> 60 | K10: 61-70% | L10: =INDEX(Assumptions!$B$10:$B$15,MATCH(K10,Assumptions!$A$10:$A$15,0)) -> 65 | M10: 3 | N10: 3 | O10: 2 | P10: 4 | Q10: 4 | R10: 3 | S10: 5 | T10: 4 | U10: =AVERAGE(O10,Q10,R10,S10) -> 3.5 | V10: =IF(U10<Assumptions!$B$5,"Low",IF(U10>=Assumptions!$B$6,"High","Medium")) -> Medium | W10: city fixed; decimal to %
A11: 10 | B11: Private | C11: Business/Management | D11: 2nd year | E11: Durgapur | F11: Percentage | G11: 64 | H11: =IF(F11="Percentage",G11,IF(OR(F11="CGPA",F11="SGPA"),G11*Assumptions!$B$3,"")) -> 64 | I11: =IF(AND(ISNUMBER(H11),H11>=Assumptions!$B$4),"Yes","No") -> Yes | J11: =IF(I11="Yes",H11,"") -> 64 | K11: 61-70% | L11: =INDEX(Assumptions!$B$10:$B$15,MATCH(K11,Assumptions!$A$10:$A$15,0)) -> 65 | M11: 5 | N11: 6 | O11: 5 | P11: 6 | Q11: 2 | R11: 5 | S11: 6 | T11: 6 | U11: =AVERAGE(O11,Q11,R11,S11) -> 4.5 | V11: =IF(U11<Assumptions!$B$5,"Low",IF(U11>=Assumptions!$B$6,"High","Medium")) -> High | W11: city fixed; decimal to %
A12: 11 | B12: Government | C12: Commerce | D12: 2nd year | E12: Durgapur | F12: SGPA | G12: 6.8 | H12: =IF(F12="Percentage",G12,IF(OR(F12="CGPA",F12="SGPA"),G12*Assumptions!$B$3,"")) -> 64.6 | I12: =IF(AND(ISNUMBER(H12),H12>=Assumptions!$B$4),"Yes","No") -> Yes | J12: =IF(I12="Yes",H12,"") -> 64.6 | K12: 51-60% | L12: =INDEX(Assumptions!$B$10:$B$15,MATCH(K12,Assumptions!$A$10:$A$15,0)) -> 55 | M12: 2 | N12: 5 | O12: 5 | P12: 5 | Q12: 5 | R12: 5 | S12: 5 | T12: 5 | U12: =AVERAGE(O12,Q12,R12,S12) -> 5 | V12: =IF(U12<Assumptions!$B$5,"Low",IF(U12>=Assumptions!$B$6,"High","Medium")) -> High | W12: city fixed; GPA to %
A13: 12 | B13: Private | C13: Arts/Humanities | D13: 1st year | E13: Murshidabad | F13: Percentage | G13: 68 | H13: =IF(F13="Percentage",G13,IF(OR(F13="CGPA",F13="SGPA"),G13*Assumptions!$B$3,"")) -> 68 | I13: =IF(AND(ISNUMBER(H13),H13>=Assumptions!$B$4),"Yes","No") -> Yes | J13: =IF(I13="Yes",H13,"") -> 68 | K13: 51-60% | L13: =INDEX(Assumptions!$B$10:$B$15,MATCH(K13,Assumptions!$A$10:$A$15,0)) -> 55 | M13: 3 | N13: 4 | O13: 3 | P13: 5 | Q13: 4 | R13: 3 | S13: 3 | T13: 4 | U13: =AVERAGE(O13,Q13,R13,S13) -> 3.25 | V13: =IF(U13<Assumptions!$B$5,"Low",IF(U13>=Assumptions!$B$6,"High","Medium")) -> Low | W13: year label fixed; decimal to %
A14: 13 | B14: Private | C14: Business/Management | D14: 2nd year | E14: Mehsana | F14: Percentage | G14: 50 | H14: =IF(F14="Percentage",G14,IF(OR(F14="CGPA",F14="SGPA"),G14*Assumptions!$B$3,"")) -> 50 | I14: =IF(AND(ISNUMBER(H14),H14>=Assumptions!$B$4),"Yes","No") -> Yes | J14: =IF(I14="Yes",H14,"") -> 50 | K14: 51-60% | L14: =INDEX(Assumptions!$B$10:$B$15,MATCH(K14,Assumptions!$A$10:$A$15,0)) -> 55 | M14: 6 | N14: 4 | O14: 6 | P14: 6 | Q14: 6 | R14: 6 | S14: 6 | T14: 1 | U14: =AVERAGE(O14,Q14,R14,S14) -> 6 | V14: =IF(U14<Assumptions!$B$5,"Low",IF(U14>=Assumptions!$B$6,"High","Medium")) -> High | W14: city fixed; decimal to %
A15: 14 | B15: Private | C15: Business/Management | D15: 3rd year | E15: Ghaziabad | F15: Percentage | G15: 70 | H15: =IF(F15="Percentage",G15,IF(OR(F15="CGPA",F15="SGPA"),G15*Assumptions!$B$3,"")) -> 70 | I15: =IF(AND(ISNUMBER(H15),H15>=Assumptions!$B$4),"Yes","No") -> Yes | J15: =IF(I15="Yes",H15,"") -> 70 | K15: 71-80% | L15: =INDEX(Assumptions!$B$10:$B$15,MATCH(K15,Assumptions!$A$10:$A$15,0)) -> 75 | M15: 5 | N15: 6 | O15: 6 | P15: 6 | Q15: 6 | R15: 6 | S15: 6 | T15: 1 | U15: =AVERAGE(O15,Q15,R15,S15) -> 6 | V15: =IF(U15<Assumptions!$B$5,"Low",IF(U15>=Assumptions!$B$6,"High","Medium")) -> High | W15: city fixed; decimal to %
A16: 15 | B16: Private | C16: Business/Management | D16: 1st year | E16: Mohali | F16: Percentage | G16: 67 | H16: =IF(F16="Percentage",G16,IF(OR(F16="CGPA",F16="SGPA"),G16*Assumptions!$B$3,"")) -> 67 | I16: =IF(AND(ISNUMBER(H16),H16>=Assumptions!$B$4),"Yes","No") -> Yes | J16: =IF(I16="Yes",H16,"") -> 67 | K16: 91-100% | L16: =INDEX(Assumptions!$B$10:$B$15,MATCH(K16,Assumptions!$A$10:$A$15,0)) -> 95 | M16: 4 | N16: 5 | O16: 3 | P16: 6 | Q16: 4 | R16: 5 | S16: 5 | T16: 5 | U16: =AVERAGE(O16,Q16,R16,S16) -> 4.25 | V16: =IF(U16<Assumptions!$B$5,"Low",IF(U16>=Assumptions!$B$6,"High","Medium")) -> Medium | W16: decimal to %
A17: 16 | B17: Government-aided | C17: Medicine/Healthcare | D17: 4th year | E17: Delhi | F17: CGPA | G17: 9.7 | H17: =IF(F17="Percentage",G17,IF(OR(F17="CGPA",F17="SGPA"),G17*Assumptions!$B$3,"")) -> 92.15 | I17: =IF(AND(ISNUMBER(H17),H17>=Assumptions!$B$4),"Yes","No") -> Yes | J17: =IF(I17="Yes",H17,"") -> 92.15 | K17: 71-80% | L17: =INDEX(Assumptions!$B$10:$B$15,MATCH(K17,Assumptions!$A$10:$A$15,0)) -> 75 | M17: 3 | N17: 4 | O17: 5 | P17: 6 | Q17: 2 | R17: 4 | S17: 5 | T17: 6 | U17: =AVERAGE(O17,Q17,R17,S17) -> 4 | V17: =IF(U17<Assumptions!$B$5,"Low",IF(U17>=Assumptions!$B$6,"High","Medium")) -> Medium | W17: GPA to %
A18: 17 | B18: Private | C18: Commerce | D18: 1st year | E18: Prayagraj | F18: CGPA | G18: 8.01 | H18: =IF(F18="Percentage",G18,IF(OR(F18="CGPA",F18="SGPA"),G18*Assumptions!$B$3,"")) -> 76.095 | I18: =IF(AND(ISNUMBER(H18),H18>=Assumptions!$B$4),"Yes","No") -> Yes | J18: =IF(I18="Yes",H18,"") -> 76.095 | K18: 71-80% | L18: =INDEX(Assumptions!$B$10:$B$15,MATCH(K18,Assumptions!$A$10:$A$15,0)) -> 75 | M18: 6 | N18: 6 | O18: 5 | P18: 4 | Q18: 5 | R18: 5 | S18: 5 | T18: 4 | U18: =AVERAGE(O18,Q18,R18,S18) -> 5 | V18: =IF(U18<Assumptions!$B$5,"Low",IF(U18>=Assumptions!$B$6,"High","Medium")) -> High | W18: city fixed; GPA to %
A19: 18 | B19: Government | C19: Engineering | D19: 1st year | E19: Burdwan | F19: CGPA | G19: 2 | H19: =IF(F19="Percentage",G19,IF(OR(F19="CGPA",F19="SGPA"),G19*Assumptions!$B$3,"")) -> 19 | I19: =IF(AND(ISNUMBER(H19),H19>=Assumptions!$B$4),"Yes","No") -> No | J19: =IF(I19="Yes",H19,"") | K19: 51-60% | L19: =INDEX(Assumptions!$B$10:$B$15,MATCH(K19,Assumptions!$A$10:$A$15,0)) -> 55 | M19: 3 | N19: 2 | O19: 3 | P19: 4 | Q19: 3 | R19: 4 | S19: 2 | T19: 1 | U19: =AVERAGE(O19,Q19,R19,S19) -> 3 | V19: =IF(U19<Assumptions!$B$5,"Low",IF(U19>=Assumptions!$B$6,"High","Medium")) -> Low | W19: city fixed; GPA to %; implausible score
... A36: 35 | B36: Government-aided | C36: Law/Science/Other | D36: 4th year | E36: Chandigarh | F36: SGPA | G36: 9.3 | H36: =IF(F36="Percentage",G36,IF(OR(F36="CGPA",F36="SGPA"),G36*Assumptions!$B$3,"")) -> 88.35 | I36: =IF(AND(ISNUMBER(H36),H36>=Assumptions!$B$4),"Yes","No") -> Yes | J36: =IF(I36="Yes",H36,"") -> 88.35 | K36: 61-70% | L36: =INDEX(Assumptions!$B$10:$B$15,MATCH(K36,Assumptions!$A$10:$A$15,0)) -> 65 | M36: 5 | N36: 3 | O36: 3 | P36: 4 | Q36: 3 | R36: 4 | S36: 4 | T36: 5 | U36: =AVERAGE(O36,Q36,R36,S36) -> 3.5 | V36: =IF(U36<Assumptions!$B$5,"Low",IF(U36>=Assumptions!$B$6,"High","Medium")) -> Medium | W36: field regrouped; GPA to %
A37: 36 | B37: Private | C37: Engineering | D37: 2nd year | E37: Amritsar | F37: Percentage | G37: 67 | H37: =IF(F37="Percentage",G37,IF(OR(F37="CGPA",F37="SGPA"),G37*Assumptions!$B$3,"")) -> 67 | I37: =IF(AND(ISNUMBER(H37),H37>=Assumptions!$B$4),"Yes","No") -> Yes | J37: =IF(I37="Yes",H37,"") -> 67 | K37: 61-70% | L37: =INDEX(Assumptions!$B$10:$B$15,MATCH(K37,Assumptions!$A$10:$A$15,0)) -> 65 | M37: 4 | O37: 3 | P37: 4 | Q37: 5 | R37: 6 | S37: 4 | T37: 6 | U37: =AVERAGE(O37,Q37,R37,S37) -> 4.5 | V37: =IF(U37<Assumptions!$B$5,"Low",IF(U37>=Assumptions!$B$6,"High","Medium")) -> High | W37: decimal to %; confidence blank
A38: 37 | B38: Government | C38: Arts/Humanities | D38: 3rd year | E38: Delhi | F38: CGPA | G38: 7.8 | H38: =IF(F38="Percentage",G38,IF(OR(F38="CGPA",F38="SGPA"),G38*Assumptions!$B$3,"")) -> 74.1 | I38: =IF(AND(ISNUMBER(H38),H38>=Assumptions!$B$4),"Yes","No") -> Yes | J38: =IF(I38="Yes",H38,"") -> 74.1 | K38: 71-80% | L38: =INDEX(Assumptions!$B$10:$B$15,MATCH(K38,Assumptions!$A$10:$A$15,0)) -> 75 | M38: 3 | N38: 4 | O38: 3 | P38: 3 | Q38: 4 | R38: 2 | S38: 4 | T38: 5 | U38: =AVERAGE(O38,Q38,R38,S38) -> 3.25 | V38: =IF(U38<Assumptions!$B$5,"Low",IF(U38>=Assumptions!$B$6,"High","Medium")) -> Low | W38: GPA to %
A39: 38 | B39: Private | C39: Engineering | D39: 3rd year | E39: Durgapur | F39: Percentage | G39: 73 | H39: =IF(F39="Percentage",G39,IF(OR(F39="CGPA",F39="SGPA"),G39*Assumptions!$B$3,"")) -> 73 | I39: =IF(AND(ISNUMBER(H39),H39>=Assumptions!$B$4),"Yes","No") -> Yes | J39: =IF(I39="Yes",H39,"") -> 73 | K39: 81-90% | L39: =INDEX(Assumptions!$B$10:$B$15,MATCH(K39,Assumptions!$A$10:$A$15,0)) -> 85 | M39: 4 | N39: 3 | O39: 2 | P39: 5 | Q39: 4 | R39: 3 | S39: 4 | T39: 5 | U39: =AVERAGE(O39,Q39,R39,S39) -> 3.25 | V39: =IF(U39<Assumptions!$B$5,"Low",IF(U39>=Assumptions!$B$6,"High","Medium")) -> Low | W39: decimal to %
A40: 39 | B40: Government-aided | C40: Arts/Humanities | D40: 3rd year | E40: Kolkata | F40: CGPA | G40: 9.5 | H40: =IF(F40="Percentage",G40,IF(OR(F40="CGPA",F40="SGPA"),G40*Assumptions!$B$3,"")) -> 90.25 | I40: =IF(AND(ISNUMBER(H40),H40>=Assumptions!$B$4),"Yes","No") -> Yes | J40: =IF(I40="Yes",H40,"") -> 90.25 | K40: 71-80% | L40: =INDEX(Assumptions!$B$10:$B$15,MATCH(K40,Assumptions!$A$10:$A$15,0)) -> 75 | M40: 3 | N40: 4 | O40: 5 | P40: 6 | Q40: 3 | R40: 4 | S40: 5 | T40: 6 | U40: =AVERAGE(O40,Q40,R40,S40) -> 4.25 | V40: =IF(U40<Assumptions!$B$5,"Low",IF(U40>=Assumptions!$B$6,"High","Medium")) -> Medium | W40: field regrouped; GPA to %
A41: 40 | B41: Government | C41: Computer Science/IT | D41: 2nd year | E41: Bardhaman | F41: CGPA | G41: 8.4 | H41: =IF(F41="Percentage",G41,IF(OR(F41="CGPA",F41="SGPA"),G41*Assumptions!$B$3,"")) -> 79.8 | I41: =IF(AND(ISNUMBER(H41),H41>=Assumptions!$B$4),"Yes","No") -> Yes | J41: =IF(I41="Yes",H41,"") -> 79.8 | K41: 71-80% | L41: =INDEX(Assumptions!$B$10:$B$15,MATCH(K41,Assumptions!$A$10:$A$15,0)) -> 75 | M41: 4 | N41: 2 | O41: 3 | P41: 1 | Q41: 3 | R41: 5 | S41: 6 | T41: 2 | U41: =AVERAGE(O41,Q41,R41,S41) -> 4.25 | V41: =IF(U41<Assumptions!$B$5,"Low",IF(U41>=Assumptions!$B$6,"High","Medium")) -> Medium | W41: city fixed; GPA to %
A42: 41 | B42: Private | C42: Medicine/Healthcare | D42: 1st year | E42: Durgapur | F42: CGPA | G42: 7.09 | H42: =IF(F42="Percentage",G42,IF(OR(F42="CGPA",F42="SGPA"),G42*Assumptions!$B$3,"")) -> 67.355 | I42: =IF(AND(ISNUMBER(H42),H42>=Assumptions!$B$4),"Yes","No") -> Yes | J42: =IF(I42="Yes",H42,"") -> 67.355 | K42: 81-90% | L42: =INDEX(Assumptions!$B$10:$B$15,MATCH(K42,Assumptions!$A$10:$A$15,0)) -> 85 | M42: 5 | N42: 3 | O42: 4 | P42: 3 | Q42: 4 | R42: 6 | S42: 4 | T42: 5 | U42: =AVERAGE(O42,Q42,R42,S42) -> 4.5 | V42: =IF(U42<Assumptions!$B$5,"Low",IF(U42>=Assumptions!$B$6,"High","Medium")) -> High | W42: GPA to %
A43: 42 | B43: Government | C43: Arts/Humanities | D43: 2nd year | E43: Asansol | F43: CGPA | G43: 7.6 | H43: =IF(F43="Percentage",G43,IF(OR(F43="CGPA",F43="SGPA"),G43*Assumptions!$B$3,"")) -> 72.2 | I43: =IF(AND(ISNUMBER(H43),H43>=Assumptions!$B$4),"Yes","No") -> Yes | J43: =IF(I43="Yes",H43,"") -> 72.2 | K43: 91-100% | L43: =INDEX(Assumptions!$B$10:$B$15,MATCH(K43,Assumptions!$A$10:$A$15,0)) -> 95 | M43: 3 | N43: 4 | O43: 3 | P43: 4 | Q43: 3 | R43: 4 | S43: 3 | T43: 4 | U43: =AVERAGE(O43,Q43,R43,S43) -> 3.25 | V43: =IF(U43<Assumptions!$B$5,"Low",IF(U43>=Assumptions!$B$6,"High","Medium")) -> Low | W43: field regrouped; GPA to %
A44: 43 | B44: Private | C44: Medicine/Healthcare | D44: 1st year | E44: Chandigarh | F44: Percentage | G44: 63 | H44: =IF(F44="Percentage",G44,IF(OR(F44="CGPA",F44="SGPA"),G44*Assumptions!$B$3,"")) -> 63 | I44: =IF(AND(ISNUMBER(H44),H44>=Assumptions!$B$4),"Yes","No") -> Yes | J44: =IF(I44="Yes",H44,"") -> 63 | K44: 71-80% | L44: =INDEX(Assumptions!$B$10:$B$15,MATCH(K44,Assumptions!$A$10:$A$15,0)) -> 75 | M44: 3 | N44: 4 | O44: 5 | P44: 5 | Q44: 4 | R44: 6 | S44: 6 | T44: 6 | U44: =AVERAGE(O44,Q44,R44,S44) -> 5.25 | V44: =IF(U44<Assumptions!$B$5,"Low",IF(U44>=Assumptions!$B$6,"High","Medium")) -> High | W44: decimal to %
A45: 44 | B45: Private | C45: Computer Science/IT | D45: 3rd year | E45: Kolkata | F45: Percentage | G45: 67 | H45: =IF(F45="Percentage",G45,IF(OR(F45="CGPA",F45="SGPA"),G45*Assumptions!$B$3,"")) -> 67 | I45: =IF(AND(ISNUMBER(H45),H45>=Assumptions!$B$4),"Yes","No") -> Yes | J45: =IF(I45="Yes",H45,"") -> 67 | K45: 61-70% | L45: =INDEX(Assumptions!$B$10:$B$15,MATCH(K45,Assumptions!$A$10:$A$15,0)) -> 65 | M45: 4 | N45: 4 | O45: 3 | P45: 4 | Q45: 4 | R45: 3 | S45: 4 | T45: 4 | U45: =AVERAGE(O45,Q45,R45,S45) -> 3.5 | V45: =IF(U45<Assumptions!$B$5,"Low",IF(U45>=Assumptions!$B$6,"High","Medium")) -> Medium | W45: decimal to %
A46: 45 | B46: Private | C46: Arts/Humanities | D46: 4th year | E46: Karnataka | F46: CGPA | G46: 7.3 | H46: =IF(F46="Percentage",G46,IF(OR(F46="CGPA",F46="SGPA"),G46*Assumptions!$B$3,"")) -> 69.35 | I46: =IF(AND(ISNUMBER(H46),H46>=Assumptions!$B$4),"Yes","No") -> Yes | J46: =IF(I46="Yes",H46,"") -> 69.35 | K46: 81-90% | L46: =INDEX(Assumptions!$B$10:$B$15,MATCH(K46,Assumptions!$A$10:$A$15,0)) -> 85 | M46: 3 | N46: 4 | O46: 5 | P46: 3 | Q46: 4 | R46: 5 | S46: 6 | T46: 3 | U46: =AVERAGE(O46,Q46,R46,S46) -> 5 | V46: =IF(U46<Assumptions!$B$5,"Low",IF(U46>=Assumptions!$B$6,"High","Medium")) -> High | W46: city fixed; GPA to %
A47: 46 | B47: Government-aided | C47: Arts/Humanities | D47: 2nd year | E47: Bengaluru | F47: Percentage | G47: 93 | H47: =IF(F47="Percentage",G47,IF(OR(F47="CGPA",F47="SGPA"),G47*Assumptions!$B$3,"")) -> 93 | I47: =IF(AND(ISNUMBER(H47),H47>=Assumptions!$B$4),"Yes","No") -> Yes | J47: =IF(I47="Yes",H47,"") -> 93 | K47: 71-80% | L47: =INDEX(Assumptions!$B$10:$B$15,MATCH(K47,Assumptions!$A$10:$A$15,0)) -> 75 | M47: 4 | N47: 3 | O47: 2 | P47: 3 | Q47: 5 | R47: 4 | S47: 3 | T47: 4 | U47: =AVERAGE(O47,Q47,R47,S47) -> 3.5 | V47: =IF(U47<Assumptions!$B$5,"Low",IF(U47>=Assumptions!$B$6,"High","Medium")) -> Medium | W47: decimal to %
A48: 47 | B48: Government-aided | C48: Medicine/Healthcare | D48: 1st year | E48: Aligarh | F48: Percentage | G48: 78 | H48: =IF(F48="Percentage",G48,IF(OR(F48="CGPA",F48="SGPA"),G48*Assumptions!$B$3,"")) -> 78 | I48: =IF(AND(ISNUMBER(H48),H48>=Assumptions!$B$4),"Yes","No") -> Yes | J48: =IF(I48="Yes",H48,"") -> 78 | K48: 51-60% | L48: =INDEX(Assumptions!$B$10:$B$15,MATCH(K48,Assumptions!$A$10:$A$15,0)) -> 55 | M48: 2 | N48: 3 | O48: 4 | P48: 3 | Q48: 4 | R48: 3 | S48: 4 | T48: 3 | U48: =AVERAGE(O48,Q48,R48,S48) -> 3.75 | V48: =IF(U48<Assumptions!$B$5,"Low",IF(U48>=Assumptions!$B$6,"High","Medium")) -> Medium | W48: decimal to %
A49: 48 | B49: Private | C49: Medicine/Healthcare | D49: 1st year | E49: Ranchi | F49: Percentage | G49: 76 | H49: =IF(F49="Percentage",G49,IF(OR(F49="CGPA",F49="SGPA"),G49*Assumptions!$B$3,"")) -> 76 | I49: =IF(AND(ISNUMBER(H49),H49>=Assumptions!$B$4),"Yes","No") -> Yes | J49: =IF(I49="Yes",H49,"") -> 76 | K49: 61-70% | L49: =INDEX(Assumptions!$B$10:$B$15,MATCH(K49,Assumptions!$A$10:$A$15,0)) -> 65 | M49: 3 | N49: 4 | O49: 3 | P49: 4 | Q49: 3 | R49: 4 | S49: 3 | T49: 4 | U49: =AVERAGE(O49,Q49,R49,S49) -> 3.25 | V49: =IF(U49<Assumptions!$B$5,"Low",IF(U49>=Assumptions!$B$6,"High","Medium")) -> Low | W49: decimal to %
... A62: 61 | B62: Private | C62: Law/Science/Other | D62: 2nd year | E62: Jaipur | F62: CGPA | G62: 7.63 | H62: =IF(F62="Percentage",G62,IF(OR(F62="CGPA",F62="SGPA"),G62*Assumptions!$B$3,"")) -> 72.485 | I62: =IF(AND(ISNUMBER(H62),H62>=Assumptions!$B$4),"Yes","No") -> Yes | J62: =IF(I62="Yes",H62,"") -> 72.485 | K62: 81-90% | L62: =INDEX(Assumptions!$B$10:$B$15,MATCH(K62,Assumptions!$A$10:$A$15,0)) -> 85 | M62: 1 | N62: 3 | O62: 3 | P62: 4 | Q62: 5 | R62: 6 | S62: 3 | T62: 5 | U62: =AVERAGE(O62,Q62,R62,S62) -> 4.25 | V62: =IF(U62<Assumptions!$B$5,"Low",IF(U62>=Assumptions!$B$6,"High","Medium")) -> Medium | W62: field regrouped; GPA to %
A63: 62 | B63: Government | C63: Engineering | D63: 4th year | E63: Madhupur | F63: Percentage | G63: 50 | H63: =IF(F63="Percentage",G63,IF(OR(F63="CGPA",F63="SGPA"),G63*Assumptions!$B$3,"")) -> 50 | I63: =IF(AND(ISNUMBER(H63),H63>=Assumptions!$B$4),"Yes","No") -> Yes | J63: =IF(I63="Yes",H63,"") -> 50 | K63: below 50% | L63: =INDEX(Assumptions!$B$10:$B$15,MATCH(K63,Assumptions!$A$10:$A$15,0)) -> 45 | M63: 6 | N63: 6 | O63: 6 | P63: 6 | Q63: 6 | R63: 6 | S63: 6 | T63: 6 | U63: =AVERAGE(O63,Q63,R63,S63) -> 6 | V63: =IF(U63<Assumptions!$B$5,"Low",IF(U63>=Assumptions!$B$6,"High","Medium")) -> High
A64: 63 | B64: Private | C64: Arts/Humanities | D64: 3rd year | E64: Jamshedpur | F64: Percentage | G64: 56 | H64: =IF(F64="Percentage",G64,IF(OR(F64="CGPA",F64="SGPA"),G64*Assumptions!$B$3,"")) -> 56 | I64: =IF(AND(ISNUMBER(H64),H64>=Assumptions!$B$4),"Yes","No") -> Yes | J64: =IF(I64="Yes",H64,"") -> 56 | K64: 61-70% | L64: =INDEX(Assumptions!$B$10:$B$15,MATCH(K64,Assumptions!$A$10:$A$15,0)) -> 65 | M64: 3 | N64: 4 | O64: 5 | P64: 5 | Q64: 6 | R64: 6 | S64: 3 | T64: 4 | U64: =AVERAGE(O64,Q64,R64,S64) -> 5 | V64: =IF(U64<Assumptions!$B$5,"Low",IF(U64>=Assumptions!$B$6,"High","Medium")) -> High | W64: decimal to %
A65: 64 | B65: Government | C65: Engineering | D65: 2nd year | E65: Ghaziabad | F65: Percentage | G65: 57.3 | H65: =IF(F65="Percentage",G65,IF(OR(F65="CGPA",F65="SGPA"),G65*Assumptions!$B$3,"")) -> 57.3 | I65: =IF(AND(ISNUMBER(H65),H65>=Assumptions!$B$4),"Yes","No") -> Yes | J65: =IF(I65="Yes",H65,"") -> 57.3 | K65: 51-60% | L65: =INDEX(Assumptions!$B$10:$B$15,MATCH(K65,Assumptions!$A$10:$A$15,0)) -> 55 | M65: 3 | N65: 4 | O65: 3 | P65: 5 | Q65: 3 | R65: 6 | S65: 4 | T65: 6 | U65: =AVERAGE(O65,Q65,R65,S65) -> 4 | V65: =IF(U65<Assumptions!$B$5,"Low",IF(U65>=Assumptions!$B$6,"High","Medium")) -> Medium | W65: decimal to %
A66: 65 | B66: Government-aided | C66: Arts/Humanities | D66: 3rd year | E66: Jaipur | F66: Percentage | G66: 89.3 | H66: =IF(F66="Percentage",G66,IF(OR(F66="CGPA",F66="SGPA"),G66*Assumptions!$B$3,"")) -> 89.3 | I66: =IF(AND(ISNUMBER(H66),H66>=Assumptions!$B$4),"Yes","No") -> Yes | J66: =IF(I66="Yes",H66,"") -> 89.3 | K66: 71-80% | L66: =INDEX(Assumptions!$B$10:$B$15,MATCH(K66,Assumptions!$A$10:$A$15,0)) -> 75 | M66: 4 | N66: 3 | O66: 5 | P66: 6 | Q66: 4 | R66: 6 | S66: 4 | T66: 6 | U66: =AVERAGE(O66,Q66,R66,S66) -> 4.75 | V66: =IF(U66<Assumptions!$B$5,"Low",IF(U66>=Assumptions!$B$6,"High","Medium")) -> High | W66: decimal to %

Sheet Analysis
A1: Analysis (every number here is a formula pointing to Cleaned Data)
A3: 1. Sample at a glance | H3: Chart helper: valid scores only (feeds the Dashboard scatter plot)
A4: Measure | B4: Value | H4: Row in Cleaned Data range | I4: Study Habit Index (1-6) | J4: Score Used (%) | L4: Valid score running count
A5: Survey responses | B5: =COUNTA('Cleaned Data'!$B$2:$B$66) -> 65 | H5: =MATCH(ROWS($H$5:H5),$L$5:$L$69,0) -> 1 | I5: =INDEX('Cleaned Data'!$U$2:$U$66,H5) -> 3.5 | J5: =INDEX('Cleaned Data'!$J$2:$J$66,H5) -> 85.12 | L5: =IF('Cleaned Data'!$I$2="Yes",COUNTIF('Cleaned Data'!$I$2:$I$2,"Yes"),"") -> 1
A6: Responses with a usable score | B6: =COUNTIF('Cleaned Data'!$I$2:$I$66,"Yes") -> 62 | H6: =MATCH(ROWS($H$5:H6),$L$5:$L$69,0) -> 2 | I6: =INDEX('Cleaned Data'!$U$2:$U$66,H6) -> 2.25 | J6: =INDEX('Cleaned Data'!$J$2:$J$66,H6) -> 78 | L6: =IF('Cleaned Data'!$I$3="Yes",COUNTIF('Cleaned Data'!$I$2:$I$3,"Yes"),"") -> 2
A7: Different cities mentioned | B7: =SUMPRODUCT(1/COUNTIF('Cleaned Data'!$E$2:$E$66,'Cleaned Data'!$E$2:$E$66)) -> 37 | H7: =MATCH(ROWS($H$5:H7),$L$5:$L$69,0) -> 3 | I7: =INDEX('Cleaned Data'!$U$2:$U$66,H7) -> 1.75 | J7: =INDEX('Cleaned Data'!$J$2:$J$66,H7) -> 70 | L7: =IF('Cleaned Data'!$I$4="Yes",COUNTIF('Cleaned Data'!$I$2:$I$4,"Yes"),"") -> 3
A8: Average score (%) | B8: =AVERAGE('Cleaned Data'!$J$2:$J$66) -> 71.031532 | H8: =MATCH(ROWS($H$5:H8),$L$5:$L$69,0) -> 4 | I8: =INDEX('Cleaned Data'!$U$2:$U$66,H8) -> 5.25 | J8: =INDEX('Cleaned Data'!$J$2:$J$66,H8) -> 87 | L8: =IF('Cleaned Data'!$I$5="Yes",COUNTIF('Cleaned Data'!$I$2:$I$5,"Yes"),"") -> 4
A9: Median score (%) | B9: =MEDIAN('Cleaned Data'!$J$2:$J$66) -> 70 | H9: =MATCH(ROWS($H$5:H9),$L$5:$L$69,0) -> 7 | I9: =INDEX('Cleaned Data'!$U$2:$U$66,H9) -> 3.5 | J9: =INDEX('Cleaned Data'!$J$2:$J$66,H9) -> 43 | L9: =IF('Cleaned Data'!$I$6="Yes",COUNTIF('Cleaned Data'!$I$2:$I$6,"Yes"),"")
A10: Standard deviation (%) | B10: =STDEV('Cleaned Data'!$J$2:$J$66) -> 11.775859 | H10: =MATCH(ROWS($H$5:H10),$L$5:$L$69,0) -> 8 | I10: =INDEX('Cleaned Data'!$U$2:$U$66,H10) -> 3 | J10: =INDEX('Cleaned Data'!$J$2:$J$66,H10) -> 61.75 | L10: =IF('Cleaned Data'!$I$7="Yes",COUNTIF('Cleaned Data'!$I$2:$I$7,"Yes"),"")
A11: Lowest score (%) | B11: =MIN('Cleaned Data'!$J$2:$J$66) -> 43 | H11: =MATCH(ROWS($H$5:H11),$L$5:$L$69,0) -> 9 | I11: =INDEX('Cleaned Data'!$U$2:$U$66,H11) -> 3.5 | J11: =INDEX('Cleaned Data'!$J$2:$J$66,H11) -> 60 | L11: =IF('Cleaned Data'!$I$8="Yes",COUNTIF('Cleaned Data'!$I$2:$I$8,"Yes"),"") -> 5
A12: Highest score (%) | B12: =MAX('Cleaned Data'!$J$2:$J$66) -> 93 | H12: =MATCH(ROWS($H$5:H12),$L$5:$L$69,0) -> 10 | I12: =INDEX('Cleaned Data'!$U$2:$U$66,H12) -> 4.5 | J12: =INDEX('Cleaned Data'!$J$2:$J$66,H12) -> 64 | L12: =IF('Cleaned Data'!$I$9="Yes",COUNTIF('Cleaned Data'!$I$2:$I$9,"Yes"),"") -> 6
A13: Middle 50% of students scored between (Q1, %) | B13: =QUARTILE('Cleaned Data'!$J$2:$J$66,1) -> 64 | H13: =MATCH(ROWS($H$5:H13),$L$5:$L$69,0) -> 11 | I13: =INDEX('Cleaned Data'!$U$2:$U$66,H13) -> 5 | J13: =INDEX('Cleaned Data'!$J$2:$J$66,H13) -> 64.6 | L13: =IF('Cleaned Data'!$I$10="Yes",COUNTIF('Cleaned Data'!$I$2:$I$10,"Yes"),"") -> 7
A14: ... and (Q3, %) | B14: =QUARTILE('Cleaned Data'!$J$2:$J$66,3) -> 78 | H14: =MATCH(ROWS($H$5:H14),$L$5:$L$69,0) -> 12 | I14: =INDEX('Cleaned Data'!$U$2:$U$66,H14) -> 3.25 | J14: =INDEX('Cleaned Data'!$J$2:$J$66,H14) -> 68 | L14: =IF('Cleaned Data'!$I$11="Yes",COUNTIF('Cleaned Data'!$I$2:$I$11,"Yes"),"") -> 8
A15: Students scoring 75% or more | B15: =COUNTIF('Cleaned Data'!$J$2:$J$66,">=75")/COUNT('Cleaned Data'!$J$2:$J$66) -> 0.37096774 | H15: =MATCH(ROWS($H$5:H15),$L$5:$L$69,0) -> 13 | I15: =INDEX('Cleaned Data'!$U$2:$U$66,H15) -> 6 | J15: =INDEX('Cleaned Data'!$J$2:$J$66,H15) -> 50 | L15: =IF('Cleaned Data'!$I$12="Yes",COUNTIF('Cleaned Data'!$I$2:$I$12,"Yes"),"") -> 9
A16: Average Study Habit Index (1-6) | B16: =AVERAGE('Cleaned Data'!$U$2:$U$66) -> 3.9153846 | H16: =MATCH(ROWS($H$5:H16),$L$5:$L$69,0) -> 14 | I16: =INDEX('Cleaned Data'!$U$2:$U$66,H16) -> 6 | J16: =INDEX('Cleaned Data'!$J$2:$J$66,H16) -> 70 | L16: =IF('Cleaned Data'!$I$13="Yes",COUNTIF('Cleaned Data'!$I$2:$I$13,"Yes"),"") -> 10
H17: =MATCH(ROWS($H$5:H17),$L$5:$L$69,0) -> 15 | I17: =INDEX('Cleaned Data'!$U$2:$U$66,H17) -> 4.25 | J17: =INDEX('Cleaned Data'!$J$2:$J$66,H17) -> 67 | L17: =IF('Cleaned Data'!$I$14="Yes",COUNTIF('Cleaned Data'!$I$2:$I$14,"Yes"),"") -> 11
A18: 2. How students rated themselves | H18: =MATCH(ROWS($H$5:H18),$L$5:$L$69,0) -> 16 | I18: =INDEX('Cleaned Data'!$U$2:$U$66,H18) -> 4 | J18: =INDEX('Cleaned Data'!$J$2:$J$66,H18) -> 92.15 | L18: =IF('Cleaned Data'!$I$15="Yes",COUNTIF('Cleaned Data'!$I$2:$I$15,"Yes"),"") -> 12
A19: Survey statement | B19: Average (of 6) | C19: Median | D19: Std dev | E19: % rating 5-6 | F19: % rating 1-2 | H19: =MATCH(ROWS($H$5:H19),$L$5:$L$69,0) -> 17 | I19: =INDEX('Cleaned Data'!$U$2:$U$66,H19) -> 5 | J19: =INDEX('Cleaned Data'!$J$2:$J$66,H19) -> 76.095 | L19: =IF('Cleaned Data'!$I$16="Yes",COUNTIF('Cleaned Data'!$I$2:$I$16,"Yes"),"") -> 13
A20: Understanding of subjects | B20: =AVERAGE('Cleaned Data'!$P$2:$P$66) -> 4.2461538 | C20: =MEDIAN('Cleaned Data'!$P$2:$P$66) -> 4 | D20: =STDEV('Cleaned Data'!$P$2:$P$66) -> 1.2123166 | E20: =COUNTIF('Cleaned Data'!$P$2:$P$66,">=5")/COUNT('Cleaned Data'!$P$2:$P$66) -> 0.4 | F20: =COUNTIF('Cleaned Data'!$P$2:$P$66,"<=2")/COUNT('Cleaned Data'!$P$2:$P$66) -> 0.046153846 | H20: =MATCH(ROWS($H$5:H20),$L$5:$L$69,0) -> 19 | I20: =INDEX('Cleaned Data'!$U$2:$U$66,H20) -> 4.25 | J20: =INDEX('Cleaned Data'!$J$2:$J$66,H20) -> 64 | L20: =IF('Cleaned Data'!$I$17="Yes",COUNTIF('Cleaned Data'!$I$2:$I$17,"Yes"),"") -> 14
A21: Focus while studying | B21: =AVERAGE('Cleaned Data'!$S$2:$S$66) -> 4.1538462 | C21: =MEDIAN('Cleaned Data'!$S$2:$S$66) -> 4 | D21: =STDEV('Cleaned Data'!$S$2:$S$66) -> 1.3137586 | E21: =COUNTIF('Cleaned Data'!$S$2:$S$66,">=5")/COUNT('Cleaned Data'!$S$2:$S$66) -> 0.4 | F21: =COUNTIF('Cleaned Data'!$S$2:$S$66,"<=2")/COUNT('Cleaned Data'!$S$2:$S$66) -> 0.10769231 | H21: =MATCH(ROWS($H$5:H21),$L$5:$L$69,0) -> 20 | I21: =INDEX('Cleaned Data'!$U$2:$U$66,H21) -> 3 | J21: =INDEX('Cleaned Data'!$J$2:$J$66,H21) -> 63.65 | L21: =IF('Cleaned Data'!$I$18="Yes",COUNTIF('Cleaned Data'!$I$2:$I$18,"Yes"),"") -> 15
A22: Time management | B22: =AVERAGE('Cleaned Data'!$R$2:$R$66) -> 4.0615385 | C22: =MEDIAN('Cleaned Data'!$R$2:$R$66) -> 4 | D22: =STDEV('Cleaned Data'!$R$2:$R$66) -> 1.3564306 | E22: =COUNTIF('Cleaned Data'!$R$2:$R$66,">=5")/COUNT('Cleaned Data'!$R$2:$R$66) -> 0.36923077 | F22: =COUNTIF('Cleaned Data'!$R$2:$R$66,"<=2")/COUNT('Cleaned Data'!$R$2:$R$66) -> 0.10769231 | H22: =MATCH(ROWS($H$5:H22),$L$5:$L$69,0) -> 21 | I22: =INDEX('Cleaned Data'!$U$2:$U$66,H22) -> 3 | J22: =INDEX('Cleaned Data'!$J$2:$J$66,H22) -> 80 | L22: =IF('Cleaned Data'!$I$19="Yes",COUNTIF('Cleaned Data'!$I$2:$I$19,"Yes"),"")
A23: Belief attendance helps marks | B23: =AVERAGE('Cleaned Data'!$T$2:$T$66) -> 3.9692308 | C23: =MEDIAN('Cleaned Data'!$T$2:$T$66) -> 4 | D23: =STDEV('Cleaned Data'!$T$2:$T$66) -> 1.530617 | E23: =COUNTIF('Cleaned Data'!$T$2:$T$66,">=5")/COUNT('Cleaned Data'!$T$2:$T$66) -> 0.35384615 | F23: =COUNTIF('Cleaned Data'!$T$2:$T$66,"<=2")/COUNT('Cleaned Data'!$T$2:$T$66) -> 0.2 | H23: =MATCH(ROWS($H$5:H23),$L$5:$L$69,0) -> 22 | I23: =INDEX('Cleaned Data'!$U$2:$U$66,H23) -> 2.75 | J23: =INDEX('Cleaned Data'!$J$2:$J$66,H23) -> 67 | L23: =IF('Cleaned Data'!$I$20="Yes",COUNTIF('Cleaned Data'!$I$2:$I$20,"Yes"),"") -> 16
A24: Confidence to perform | B24: =AVERAGE('Cleaned Data'!$N$2:$N$66) -> 3.96875 | C24: =MEDIAN('Cleaned Data'!$N$2:$N$66) -> 4 | D24: =STDEV('Cleaned Data'!$N$2:$N$66) -> 1.1542709 | E24: =COUNTIF('Cleaned Data'!$N$2:$N$66,">=5")/COUNT('Cleaned Data'!$N$2:$N$66) -> 0.265625 | F24: =COUNTIF('Cleaned Data'!$N$2:$N$66,"<=2")/COUNT('Cleaned Data'!$N$2:$N$66) -> 0.09375 | H24: =MATCH(ROWS($H$5:H24),$L$5:$L$69,0) -> 23 | I24: =INDEX('Cleaned Data'!$U$2:$U$66,H24) -> 1.5 | J24: =INDEX('Cleaned Data'!$J$2:$J$66,H24) -> 59.85 | L24: =IF('Cleaned Data'!$I$21="Yes",COUNTIF('Cleaned Data'!$I$2:$I$21,"Yes"),"") -> 17
A25: Motivation to study | B25: =AVERAGE('Cleaned Data'!$Q$2:$Q$66) -> 3.8615385 | C25: =MEDIAN('Cleaned Data'!$Q$2:$Q$66) -> 4 | D25: =STDEV('Cleaned Data'!$Q$2:$Q$66) -> 1.2732454 | E25: =COUNTIF('Cleaned Data'!$Q$2:$Q$66,">=5")/COUNT('Cleaned Data'!$Q$2:$Q$66) -> 0.32307692 | F25: =COUNTIF('Cleaned Data'!$Q$2:$Q$66,"<=2")/COUNT('Cleaned Data'!$Q$2:$Q$66) -> 0.10769231 | H25: =MATCH(ROWS($H$5:H25),$L$5:$L$69,0) -> 24 | I25: =INDEX('Cleaned Data'!$U$2:$U$66,H25) -> 2 | J25: =INDEX('Cleaned Data'!$J$2:$J$66,H25) -> 65 | L25: =IF('Cleaned Data'!$I$22="Yes",COUNTIF('Cleaned Data'!$I$2:$I$22,"Yes"),"") -> 18
A26: Satisfaction with performance | B26: =AVERAGE('Cleaned Data'!$M$2:$M$66) -> 3.6615385 | C26: =MEDIAN('Cleaned Data'!$M$2:$M$66) -> 4 | D26: =STDEV('Cleaned Data'!$M$2:$M$66) -> 1.1894973 | E26: =COUNTIF('Cleaned Data'!$M$2:$M$66,">=5")/COUNT('Cleaned Data'!$M$2:$M$66) -> 0.21538462 | F26: =COUNTIF('Cleaned Data'!$M$2:$M$66,"<=2")/COUNT('Cleaned Data'!$M$2:$M$66) -> 0.12307692 | H26: =MATCH(ROWS($H$5:H26),$L$5:$L$69,0) -> 25 | I26: =INDEX('Cleaned Data'!$U$2:$U$66,H26) -> 4 | J26: =INDEX('Cleaned Data'!$J$2:$J$66,H26) -> 70 | L26: =IF('Cleaned Data'!$I$23="Yes",COUNTIF('Cleaned Data'!$I$2:$I$23,"Yes"),"") -> 19
A27: Consistency of study routine | B27: =AVERAGE('Cleaned Data'!$O$2:$O$66) -> 3.5846154 | C27: =MEDIAN('Cleaned Data'!$O$2:$O$66) -> 3 | D27: =STDEV('Cleaned Data'!$O$2:$O$66) -> 1.3097269 | E27: =COUNTIF('Cleaned Data'!$O$2:$O$66,">=5")/COUNT('Cleaned Data'!$O$2:$O$66) -> 0.27692308 | F27: =COUNTIF('Cleaned Data'!$O$2:$O$66,"<=2")/COUNT('Cleaned Data'!$O$2:$O$66) -> 0.2 | H27: =MATCH(ROWS($H$5:H27),$L$5:$L$69,0) -> 26 | I27: =INDEX('Cleaned Data'!$U$2:$U$66,H27) -> 4.25 | J27: =INDEX('Cleaned Data'!$J$2:$J$66,H27) -> 63 | L27: =IF('Cleaned Data'!$I$24="Yes",COUNTIF('Cleaned Data'!$I$2:$I$24,"Yes"),"") -> 20
H28: =MATCH(ROWS($H$5:H28),$L$5:$L$69,0) -> 27 | I28: =INDEX('Cleaned Data'!$U$2:$U$66,H28) -> 6 | J28: =INDEX('Cleaned Data'!$J$2:$J$66,H28) -> 70 | L28: =IF('Cleaned Data'!$I$25="Yes",COUNTIF('Cleaned Data'!$I$2:$I$25,"Yes"),"") -> 21
H29: =MATCH(ROWS($H$5:H29),$L$5:$L$69,0) -> 28 | I29: =INDEX('Cleaned Data'!$U$2:$U$66,H29) -> 5.5 | J29: =INDEX('Cleaned Data'!$J$2:$J$66,H29) -> 70 | L29: =IF('Cleaned Data'!$I$26="Yes",COUNTIF('Cleaned Data'!$I$2:$I$26,"Yes"),"") -> 22
A30: 3. By institution type | H30: =MATCH(ROWS($H$5:H30),$L$5:$L$69,0) -> 29 | I30: =INDEX('Cleaned Data'!$U$2:$U$66,H30) -> 3.25 | J30: =INDEX('Cleaned Data'!$J$2:$J$66,H30) -> 76.855 | L30: =IF('Cleaned Data'!$I$27="Yes",COUNTIF('Cleaned Data'!$I$2:$I$27,"Yes"),"") -> 23
A31: Institution type | B31: Students | C31: With score | D31: Avg score (%) | E31: Avg habit index | F31: Avg satisfaction | H31: =MATCH(ROWS($H$5:H31),$L$5:$L$69,0) -> 30 | I31: =INDEX('Cleaned Data'!$U$2:$U$66,H31) -> 1.75 | J31: =INDEX('Cleaned Data'!$J$2:$J$66,H31) -> 80 | L31: =IF('Cleaned Data'!$I$28="Yes",COUNTIF('Cleaned Data'!$I$2:$I$28,"Yes"),"") -> 24
A32: Private | B32: =COUNTIF('Cleaned Data'!$B$2:$B$66,A32) -> 34 | C32: =COUNTIFS('Cleaned Data'!$B$2:$B$66,A32,'Cleaned Data'!$I$2:$I$66,"Yes") -> 33 | D32: =IFERROR(AVERAGEIFS('Cleaned Data'!$J$2:$J$66,'Cleaned Data'!$B$2:$B$66,A32),"") -> 69.236061 | E32: =IFERROR(AVERAGEIFS('Cleaned Data'!$U$2:$U$66,'Cleaned Data'!$B$2:$B$66,A32),"") -> 3.9485294 | F32: =IFERROR(AVERAGEIFS('Cleaned Data'!$M$2:$M$66,'Cleaned Data'!$B$2:$B$66,A32),"") -> 3.6176471 | H32: =MATCH(ROWS($H$5:H32),$L$5:$L$69,0) -> 31 | I32: =INDEX('Cleaned Data'!$U$2:$U$66,H32) -> 5.75 | J32: =INDEX('Cleaned Data'!$J$2:$J$66,H32) -> 74.1 | L32: =IF('Cleaned Data'!$I$29="Yes",COUNTIF('Cleaned Data'!$I$2:$I$29,"Yes"),"") -> 25
A33: Government | B33: =COUNTIF('Cleaned Data'!$B$2:$B$66,A33) -> 18 | C33: =COUNTIFS('Cleaned Data'!$B$2:$B$66,A33,'Cleaned Data'!$I$2:$I$66,"Yes") -> 16 | D33: =IFERROR(AVERAGEIFS('Cleaned Data'!$J$2:$J$66,'Cleaned Data'!$B$2:$B$66,A33),"") -> 67.521563 | E33: =IFERROR(AVERAGEIFS('Cleaned Data'!$U$2:$U$66,'Cleaned Data'!$B$2:$B$66,A33),"") -> 4.0972222 | F33: =IFERROR(AVERAGEIFS('Cleaned Data'!$M$2:$M$66,'Cleaned Data'!$B$2:$B$66,A33),"") -> 3.6111111 | H33: =MATCH(ROWS($H$5:H33),$L$5:$L$69,0) -> 32 | I33: =INDEX('Cleaned Data'!$U$2:$U$66,H33) -> 4.5 | J33: =INDEX('Cleaned Data'!$J$2:$J$66,H33) -> 78 | L33: =IF('Cleaned Data'!$I$30="Yes",COUNTIF('Cleaned Data'!$I$2:$I$30,"Yes"),"") -> 26
A34: Government-aided | B34: =COUNTIF('Cleaned Data'!$B$2:$B$66,A34) -> 12 | C34: =COUNTIFS('Cleaned Data'!$B$2:$B$66,A34,'Cleaned Data'!$I$2:$I$66,"Yes") -> 12 | D34: =IFERROR(AVERAGEIFS('Cleaned Data'!$J$2:$J$66,'Cleaned Data'!$B$2:$B$66,A34),"") -> 79.068333 | E34: =IFERROR(AVERAGEIFS('Cleaned Data'!$U$2:$U$66,'Cleaned Data'!$B$2:$B$66,A34),"") -> 3.5208333 | F34: =IFERROR(AVERAGEIFS('Cleaned Data'!$M$2:$M$66,'Cleaned Data'!$B$2:$B$66,A34),"") -> 3.75 | H34: =MATCH(ROWS($H$5:H34),$L$5:$L$69,0) -> 33 | I34: =INDEX('Cleaned Data'!$U$2:$U$66,H34) -> 4.25 | J34: =INDEX('Cleaned Data'!$J$2:$J$66,H34) -> 90 | L34: =IF('Cleaned Data'!$I$31="Yes",COUNTIF('Cleaned Data'!$I$2:$I$31,"Yes"),"") -> 27
A35: Other (Non-profit) | B35: =COUNTIF('Cleaned Data'!$B$2:$B$66,A35) -> 1 | C35: =COUNTIFS('Cleaned Data'!$B$2:$B$66,A35,'Cleaned Data'!$I$2:$I$66,"Yes") -> 1 | D35: =IFERROR(AVERAGEIFS('Cleaned Data'!$J$2:$J$66,'Cleaned Data'!$B$2:$B$66,A35),"") -> 90 | E35: =IFERROR(AVERAGEIFS('Cleaned Data'!$U$2:$U$66,'Cleaned Data'!$B$2:$B$66,A35),"") -> 4.25 | F35: =IFERROR(AVERAGEIFS('Cleaned Data'!$M$2:$M$66,'Cleaned Data'!$B$2:$B$66,A35),"") -> 5 | H35: =MATCH(ROWS($H$5:H35),$L$5:$L$69,0) -> 34 | I35: =INDEX('Cleaned Data'!$U$2:$U$66,H35) -> 5 | J35: =INDEX('Cleaned Data'!$J$2:$J$66,H35) -> 78 | L35: =IF('Cleaned Data'!$I$32="Yes",COUNTIF('Cleaned Data'!$I$2:$I$32,"Yes"),"") -> 28
A36: Only 1 student in the non-profit group, so I do not compare it with the others. | H36: =MATCH(ROWS($H$5:H36),$L$5:$L$69,0) -> 35 | I36: =INDEX('Cleaned Data'!$U$2:$U$66,H36) -> 3.5 | J36: =INDEX('Cleaned Data'!$J$2:$J$66,H36) -> 88.35 | L36: =IF('Cleaned Data'!$I$33="Yes",COUNTIF('Cleaned Data'!$I$2:$I$33,"Yes"),"") -> 29
H37: =MATCH(ROWS($H$5:H37),$L$5:$L$69,0) -> 36 | I37: =INDEX('Cleaned Data'!$U$2:$U$66,H37) -> 4.5 | J37: =INDEX('Cleaned Data'!$J$2:$J$66,H37) -> 67 | L37: =IF('Cleaned Data'!$I$34="Yes",COUNTIF('Cleaned Data'!$I$2:$I$34,"Yes"),"") -> 30
H38: =MATCH(ROWS($H$5:H38),$L$5:$L$69,0) -> 37 | I38: =INDEX('Cleaned Data'!$U$2:$U$66,H38) -> 3.25 | J38: =INDEX('Cleaned Data'!$J$2:$J$66,H38) -> 74.1 | L38: =IF('Cleaned Data'!$I$35="Yes",COUNTIF('Cleaned Data'!$I$2:$I$35,"Yes"),"") -> 31
A39: 4. By field of study | H39: =MATCH(ROWS($H$5:H39),$L$5:$L$69,0) -> 38 | I39: =INDEX('Cleaned Data'!$U$2:$U$66,H39) -> 3.25 | J39: =INDEX('Cleaned Data'!$J$2:$J$66,H39) -> 73 | L39: =IF('Cleaned Data'!$I$36="Yes",COUNTIF('Cleaned Data'!$I$2:$I$36,"Yes"),"") -> 32
A40: Field of study | B40: Students | C40: With score | D40: Avg score (%) | E40: Avg habit index | F40: Avg satisfaction | H40: =MATCH(ROWS($H$5:H40),$L$5:$L$69,0) -> 39 | I40: =INDEX('Cleaned Data'!$U$2:$U$66,H40) -> 4.25 | J40: =INDEX('Cleaned Data'!$J$2:$J$66,H40) -> 90.25 | L40: =IF('Cleaned Data'!$I$37="Yes",COUNTIF('Cleaned Data'!$I$2:$I$37,"Yes"),"") -> 33
A41: Arts/Humanities | B41: =COUNTIF('Cleaned Data'!$C$2:$C$66,A41) -> 16 | C41: =COUNTIFS('Cleaned Data'!$C$2:$C$66,A41,'Cleaned Data'!$I$2:$I$66,"Yes") -> 16 | D41: =IFERROR(AVERAGEIFS('Cleaned Data'!$J$2:$J$66,'Cleaned Data'!$C$2:$C$66,A41),"") -> 72.803125 | E41: =IFERROR(AVERAGEIFS('Cleaned Data'!$U$2:$U$66,'Cleaned Data'!$C$2:$C$66,A41),"") -> 3.75 | F41: =IFERROR(AVERAGEIFS('Cleaned Data'!$M$2:$M$66,'Cleaned Data'!$C$2:$C$66,A41),"") -> 3.25 | H41: =MATCH(ROWS($H$5:H41),$L$5:$L$69,0) -> 40 | I41: =INDEX('Cleaned Data'!$U$2:$U$66,H41) -> 4.25 | J41: =INDEX('Cleaned Data'!$J$2:$J$66,H41) -> 79.8 | L41: =IF('Cleaned Data'!$I$38="Yes",COUNTIF('Cleaned Data'!$I$2:$I$38,"Yes"),"") -> 34
...

Sheet Dashboard
B2: Student Academic Performance Analytics
B3: Excel-Based Business Analytics Project | 65 survey responses on marks, attendance and study habits | Shristi Sharma
B5: SURVEY RESPONSES | F5: AVERAGE SCORE | J5: MEDIAN SCORE | N5: STUDY HABIT INDEX (1-6)
B6: =Analysis!B5 -> 65 | F6: =Analysis!B8 -> 71.031532 | J6: =Analysis!B9 -> 70 | N6: =Analysis!B16 -> 3.9153846
B8: students surveyed | F8: mean of students with a usable score | J8: half scored above this | N8: Average of consistency, motivation, time management and focus ratings.
B10: Visual analysis
J49: What the data says
J50: PERFORMANCE
J51: ="Average score "&TEXT(Analysis!B8,"0.0")&"%, median "&TEXT(Analysis!B9,"0.0")&"%. The middle 50% of students scored between "&TEXT(Analysis!B13,"0")&"% and "&TEXT(Analysis!B14,"0")&"%." -> Average score 71.0%, median 70.0%. The middle 50% of students scored between 64% and 78%.
J55: ATTENDANCE
J56: ="Attendance vs marks: r = "&TEXT(Analysis!B77,"0.00")&" ("&LOWER(Analysis!C77)&IF(Analysis!B77>=0," positive"," negative")&" link). The 71-80% group averaged "&TEXT(Analysis!D63,"0.0")&"% vs "&TEXT(Analysis!D60,"0.0")&"% below 50%." -> Attendance vs marks: r = 0.25 (weak positive link). The 71-80% group averaged 77.6% vs 64.1% below 50%.
J60: STUDY HABITS
J61: ="Habit Index vs marks: r = "&TEXT(Analysis!B78,"0.00")&" ("&LOWER(Analysis!C78)&"). Habits moved with confidence (r = "&TEXT(Analysis!B91,"0.00")&"), not with marks." -> Habit Index vs marks: r = -0.07 (very weak). Habits moved with confidence (r = 0.54), not with marks.
B67: Keep in mind: 65 students reached directly, not a random sample. Marks and ratings are self-reported, so treat these as patterns in this group, not facts about all students. Correlation does not prove cause. Longer explanations are on the Analysis sheet.

Sheet Assumptions
A1: Assumptions (blue cells can be changed, everything else updates)
A2: Item | B2: Value | C2: Why
A3: CGPA / SGPA to % multiplier | B3: 9.5 | C3: Conversion assumption used for this project: CGPA/SGPA x 9.5. Verify against the respondent's university grading rule where available.
A4: Lowest believable score (%) | B4: 30 | C4: Anything below this is treated as a typing mistake and left out of score analysis (one 2 CGPA answer).
A5: Low study habit if index is below | B5: 3.5 | C5: Cut-off I chose myself to split students into Low / Medium / High habit groups.
A6: High study habit if index is at least | B6: 4.5 | C6: Same idea, upper cut-off.
A9: Attendance band | B9: Midpoint used (%) | C9: Note
A10: below 50% | B10: 45 | C10: Bands are ranges, so I used the middle of each as a single number for correlation.
A11: 51-60% | B11: 55
A12: 61-70% | B12: 65
A13: 71-80% | B13: 75
A14: 81-90% | B14: 85
A15: 91-100% | B15: 95
A17: Rating scale: survey answers were recorded from 1 to 6 (1 = lowest, 6 = highest). Study Habit Index (1-6) = average of consistency, motivation, time management and focus ratings.
